Workbook
Name Assists: 'Section 1 '!$E$16:$E$27
Name Attendance: 'Section 2'!$J$15:$J$22
Name Avg_Attendance: 'Section 2'!$B$15:$B$22
Name Capacity: 'Section 2'!$F$15:$F$22
Name CLEANID: _xlfn.LAMBDA(_xlpm.cell,TRIM(CLEAN(SUBSTITUTE(SUBSTITUTE(SUBSTITUTE(SUBSTITUTE(_xlpm.cell,_xlfn.UNICHAR(8203),""),_xlfn.UNICHAR(8204),""),_xlfn.UNICHAR(65279),"")," ",""))))
Name Coach_Name: 'Section 2'!$H$15:$H$22
Name Goals: 'Section 1 '!$D$16:$D$27
Name League: 'Section 2'!$D$15:$D$22
Name MarketValue: 'Section 1 '!$J$16:$J$27
Name Matches: 'Section 1 '!$F$16:$F$27
Name PlayerName: 'Section 1 '!$A$16:$A$27
Name PLAYERVALUE: _xlfn.LAMBDA(_xlpm.goals,_xlpm.assists,_xlpm.salary,(_xlpm.goals*2+_xlpm.assists)*1000000/_xlpm.salary)
Name Position: 'Section 1 '!$B$16:$B$27
Name RedCards: 'Section 1 '!$H$16:$H$27
Name Revenue: 'Section 2'!$I$15:$I$22
Name Salary: 'Section 1 '!$I$16:$I$27
Name Stadium: 'Section 2'!$E$15:$E$22
Name Team_ID: 'Section 2'!$A$15:$A$22
Name Team_Name: 'Section 2'!$C$15:$C$22
Name Ticket_Price: 'Section 2'!$G$15:$G$22
Name YellowCards: 'Section 1 '!$G$16:$G$27

Sheet Section 1 
A1: SECTION 1: PLAYER PERFORMANCE
W2: Q# | X2: max | Z2: score
A3: 0) Use NAME MANAGER: Name columns PlayerName, Goals, Assists, Matches, Salary, MarketValue, YellowCards, RedCards, Position | W3: Q0 | X3: 1 | Y3: 1 | Z3: =Y3*X3 -> 1
A4: 1) TOTAL POINTS = Goals*2 + Assists*1 | W4: Q1 | X4: 1 | Y4: 1 | Z4: =Y4*X4 -> 1
A5: 2) POINTS PER MATCH = Total Points / Matches (2 decimals) | W5: Q2 | X5: 2 | Y5: 1 | Z5: =Y5*X5 -> 2
A6: 3) DISCIPLINE SCORE = 10 - (YellowCards*0.3 + RedCards*2), the maximun score is 10 and the min must be 0 | W6: Q3 | X6: 2 | Y6: 1 | Z6: =Y6*X6 -> 2
A7: 4) PERFORMANCE RATING - using the points/math insert the following >=2:'Elite', >=1.5:'Excellent', >=1:'Good', >=0.5:'Average', other:'Below Average' | W7: Q4 | X7: 2 | Y7: 1 | Z7: =Y7*X7 -> 2
A8: 5) VALUE PER POINT = MarketValue / Total Points - Use No Goals/Assists' if error | W8: Q5 | X8: 5 | Y8: 1 | Z8: =Y8*X8 -> 5
A9: 6) COST PER POINT = Salary / Total Points - Use 'No data' if error | W9: Q6 | X9: 2 | Y9: 1 | Z9: =Y9*X9 -> 2
A10: 7) CONTRACT STATUS - with YEAR(ContractEnd): <=2025:'Urgent', =2026:'Soon', >=2027:'Long Term' | W10: Q7 | X10: 5 | Y10: 1 | Z10: =Y10*X10 -> 5
A11: 8) INVESTMENT PRIORITY - use this combined criterias(Rating='Elite',Age<28):'A', AND(Rating='Excellent',Age<30):'B', Rating='Good':'C', other:'Monitor' | W11: Q8 | X11: 5 | Y11: 1 | Z11: =Y11*X11 -> 5
A12: 9) LET FORMULA: Using LET, define TotalPts=Goals*2+Assists, AvgPts=TotalPts/Matches, then return IF(AvgPts>=1.5,"Star","Regular") — all in ONE formula | W12: Q9 | X12: 5 | Y12: 1 | Z12: =Y12*X12 -> 5
A13: 10) LAMBDA: Create a named LAMBDA 'PLAYERVALUE' that takes (goals,assists,salary) and returns (goals*2+assists)*1000000/salary. Then use it for each player. | W13: Q10 | X13: 5 | Y13: 1 | Z13: =Y13*X13 -> 5
L14: Q1 | M14: Q2 | N14: Q3 | O14: Q4 | P14: Q5 | Q14: Q6 | R14: Q7 | S14: Q8 | T14: Q9 | U14: Q10 | X14: =SUM(X3:X13) -> 35 | Y14: total | Z14: =SUM(Z3:Z13) -> 35
A15: Player Name | B15: Position | C15: Age | D15: Goals | E15: Assists | F15: Matches | G15: Yellow Cards | H15: Red Cards | I15: Salary ($) | J15: Market Value ($) | K15: Contract End | L15: Total Points | M15: Points/Match | N15: Discipline Score | O15: Performance Rating | P15: Value Per Point | Q15: Cost Per Point | R15: Contract Status | S15: Investment Priority | T15: LET Star/Regular | U15: LAMBDA Value
A16: Lionel Martinez | B16: FW | C16: 27 | D16: 28 | E16: 15 | F16: 35 | G16: 3 | H16: 0 | I16: 5000000 | J16: 80000000 | K16: 0.01 | L16: =D16*2+E16 -> 71 | M16: =ROUND(L16/F16,2) -> 2.03 | N16: =MAX(0,MIN(10,10-(G16*0.3+H16*2))) -> 9.1 | O16: =IF(M16>=2,"Elite",IF(M16>=1.5,"Excellent",IF(M16>=1,"Good",IF(M16>=0.5,"Average","Below Average")))) -> Elite | P16: =IFERROR(J16/L16,"No Goals/Assists") -> 1126760.6 | Q16: =IFERROR(I16/L16,"No data") -> 70422.535 | R16: =IF(YEAR(K16)<=2025,"Urgent",IF(YEAR(K16)=2026,"Soon","Long Term")) -> Urgent | S16: =IF(AND(O16="Elite",C16<28),"A",IF(AND(O16="Excellent",C16<30),"B",IF(O16="Good","C","Monitor"))) -> A | T16: =_xlfn.LET(_xlpm.TotalPts,D16*2+E16,_xlpm.AvgPts,_xlpm.TotalPts/F16,IF(_xlpm.AvgPts>=1.5,"Star","Regular")) -> Star | U16: {=PLAYERVALUE(D16,E16,I16)} -> 14.2
A17: Cristian Rodriguez | B17: MF | C17: 31 | D17: 32 | E17: 10 | F17: 38 | G17: 5 | H17: 1 | I17: 6000000 | J17: 75000000 | K17: 46022 | L17: =D17*2+E17 -> 74 | M17: =ROUND(L17/F17,2) -> 1.95 | N17: =MAX(0,MIN(10,10-(G17*0.3+H17*2))) -> 6.5 | O17: =IF(M17>=2,"Elite",IF(M17>=1.5,"Excellent",IF(M17>=1,"Good",IF(M17>=0.5,"Average","Below Average")))) -> Excellent | P17: =IFERROR(J17/L17,"No Goals/Assists") -> 1013513.5 | Q17: =IFERROR(I17/L17,"No data") -> 81081.081 | R17: =IF(YEAR(K17)<=2025,"Urgent",IF(YEAR(K17)=2026,"Soon","Long Term")) -> Urgent | S17: =IF(AND(O17="Elite",C17<28),"A",IF(AND(O17="Excellent",C17<30),"B",IF(O17="Good","C","Monitor"))) -> Monitor | T17: =_xlfn.LET(_xlpm.TotalPts,D17*2+E17,_xlpm.AvgPts,_xlpm.TotalPts/F17,IF(_xlpm.AvgPts>=1.5,"Star","Regular")) -> Star | U17: {=PLAYERVALUE(D17,E17,I17)} -> 12.333333
A18: Kevin Anderson | B18: MF | C18: 25 | D18: 18 | E18: 22 | F18: 36 | G18: 2 | H18: 0 | I18: 3500000 | J18: 55000000 | K18: 46568 | L18: =D18*2+E18 -> 58 | M18: =ROUND(L18/F18,2) -> 1.61 | N18: =MAX(0,MIN(10,10-(G18*0.3+H18*2))) -> 9.4 | O18: =IF(M18>=2,"Elite",IF(M18>=1.5,"Excellent",IF(M18>=1,"Good",IF(M18>=0.5,"Average","Below Average")))) -> Excellent | P18: =IFERROR(J18/L18,"No Goals/Assists") -> 948275.86 | Q18: =IFERROR(I18/L18,"No data") -> 60344.828 | R18: =IF(YEAR(K18)<=2025,"Urgent",IF(YEAR(K18)=2026,"Soon","Long Term")) -> Long Term | S18: =IF(AND(O18="Elite",C18<28),"A",IF(AND(O18="Excellent",C18<30),"B",IF(O18="Good","C","Monitor"))) -> B | T18: =_xlfn.LET(_xlpm.TotalPts,D18*2+E18,_xlpm.AvgPts,_xlpm.TotalPts/F18,IF(_xlpm.AvgPts>=1.5,"Star","Regular")) -> Star | U18: {=PLAYERVALUE(D18,E18,I18)} -> 16.571429
A19: Robert Silva | B19: FW | C19: 28 | D19: 24 | E19: 12 | F19: 33 | G19: 4 | H19: 0 | I19: 4200000 | J19: 60000000 | K19: 46387 | L19: =D19*2+E19 -> 60 | M19: =ROUND(L19/F19,2) -> 1.82 | N19: =MAX(0,MIN(10,10-(G19*0.3+H19*2))) -> 8.8 | O19: =IF(M19>=2,"Elite",IF(M19>=1.5,"Excellent",IF(M19>=1,"Good",IF(M19>=0.5,"Average","Below Average")))) -> Excellent | P19: =IFERROR(J19/L19,"No Goals/Assists") -> 1000000 | Q19: =IFERROR(I19/L19,"No data") -> 70000 | R19: =IF(YEAR(K19)<=2025,"Urgent",IF(YEAR(K19)=2026,"Soon","Long Term")) -> Soon | S19: =IF(AND(O19="Elite",C19<28),"A",IF(AND(O19="Excellent",C19<30),"B",IF(O19="Good","C","Monitor"))) -> B | T19: =_xlfn.LET(_xlpm.TotalPts,D19*2+E19,_xlpm.AvgPts,_xlpm.TotalPts/F19,IF(_xlpm.AvgPts>=1.5,"Star","Regular")) -> Star | U19: {=PLAYERVALUE(D19,E19,I19)} -> 14.285714
A20: Mohamed Hassan | B20: DF | C20: 29 | D20: 15 | E20: 8 | F20: 30 | G20: 6 | H20: 1 | I20: 2800000 | J20: 35000000 | K20: 45838 | L20: =D20*2+E20 -> 38 | M20: =ROUND(L20/F20,2) -> 1.27 | N20: =MAX(0,MIN(10,10-(G20*0.3+H20*2))) -> 6.2 | O20: =IF(M20>=2,"Elite",IF(M20>=1.5,"Excellent",IF(M20>=1,"Good",IF(M20>=0.5,"Average","Below Average")))) -> Good | P20: =IFERROR(J20/L20,"No Goals/Assists") -> 921052.63 | Q20: =IFERROR(I20/L20,"No data") -> 73684.211 | R20: =IF(YEAR(K20)<=2025,"Urgent",IF(YEAR(K20)=2026,"Soon","Long Term")) -> Urgent | S20: =IF(AND(O20="Elite",C20<28),"A",IF(AND(O20="Excellent",C20<30),"B",IF(O20="Good","C","Monitor"))) -> C | T20: =_xlfn.LET(_xlpm.TotalPts,D20*2+E20,_xlpm.AvgPts,_xlpm.TotalPts/F20,IF(_xlpm.AvgPts>=1.5,"Star","Regular")) -> Regular | U20: {=PLAYERVALUE(D20,E20,I20)} -> 13.571429
A21: James Wilson | B21: FW | C21: 26 | D21: 20 | E21: 18 | F21: 34 | G21: 1 | H21: 0 | I21: 4500000 | J21: 65000000 | K21: 46934 | L21: =D21*2+E21 -> 58 | M21: =ROUND(L21/F21,2) -> 1.71 | N21: =MAX(0,MIN(10,10-(G21*0.3+H21*2))) -> 9.7 | O21: =IF(M21>=2,"Elite",IF(M21>=1.5,"Excellent",IF(M21>=1,"Good",IF(M21>=0.5,"Average","Below Average")))) -> Excellent | P21: =IFERROR(J21/L21,"No Goals/Assists") -> 1120689.7 | Q21: =IFERROR(I21/L21,"No data") -> 77586.207 | R21: =IF(YEAR(K21)<=2025,"Urgent",IF(YEAR(K21)=2026,"Soon","Long Term")) -> Long Term | S21: =IF(AND(O21="Elite",C21<28),"A",IF(AND(O21="Excellent",C21<30),"B",IF(O21="Good","C","Monitor"))) -> B | T21: =_xlfn.LET(_xlpm.TotalPts,D21*2+E21,_xlpm.AvgPts,_xlpm.TotalPts/F21,IF(_xlpm.AvgPts>=1.5,"Star","Regular")) -> Star | U21: {=PLAYERVALUE(D21,E21,I21)} -> 12.888889
A22: Luis Fernandez | B22: MF | C22: 30 | D22: 12 | E22: 25 | F22: 37 | G22: 3 | H22: 0 | I22: 3800000 | J22: 50000000 | K22: 46203 | L22: =D22*2+E22 -> 49 | M22: =ROUND(L22/F22,2) -> 1.32 | N22: =MAX(0,MIN(10,10-(G22*0.3+H22*2))) -> 9.1 | O22: =IF(M22>=2,"Elite",IF(M22>=1.5,"Excellent",IF(M22>=1,"Good",IF(M22>=0.5,"Average","Below Average")))) -> Good | P22: =IFERROR(J22/L22,"No Goals/Assists") -> 1020408.2 | Q22: =IFERROR(I22/L22,"No data") -> 77551.02 | R22: =IF(YEAR(K22)<=2025,"Urgent",IF(YEAR(K22)=2026,"Soon","Long Term")) -> Soon | S22: =IF(AND(O22="Elite",C22<28),"A",IF(AND(O22="Excellent",C22<30),"B",IF(O22="Good","C","Monitor"))) -> C | T22: =_xlfn.LET(_xlpm.TotalPts,D22*2+E22,_xlpm.AvgPts,_xlpm.TotalPts/F22,IF(_xlpm.AvgPts>=1.5,"Star","Regular")) -> Regular | U22: {=PLAYERVALUE(D22,E22,I22)} -> 12.894737
A23: Marco Rossi | B23: DF | C23: 32 | D23: 22 | E23: 14 | F23: 32 | G23: 7 | H23: 2 | I23: 4000000 | J23: 58000000 | K23: 46752 | L23: =D23*2+E23 -> 58 | M23: =ROUND(L23/F23,2) -> 1.81 | N23: =MAX(0,MIN(10,10-(G23*0.3+H23*2))) -> 3.9 | O23: =IF(M23>=2,"Elite",IF(M23>=1.5,"Excellent",IF(M23>=1,"Good",IF(M23>=0.5,"Average","Below Average")))) -> Excellent | P23: =IFERROR(J23/L23,"No Goals/Assists") -> 1000000 | Q23: =IFERROR(I23/L23,"No data") -> 68965.517 | R23: =IF(YEAR(K23)<=2025,"Urgent",IF(YEAR(K23)=2026,"Soon","Long Term")) -> Long Term | S23: =IF(AND(O23="Elite",C23<28),"A",IF(AND(O23="Excellent",C23<30),"B",IF(O23="Good","C","Monitor"))) -> Monitor | T23: =_xlfn.LET(_xlpm.TotalPts,D23*2+E23,_xlpm.AvgPts,_xlpm.TotalPts/F23,IF(_xlpm.AvgPts>=1.5,"Star","Regular")) -> Star | U23: {=PLAYERVALUE(D23,E23,I23)} -> 14.5
A24: Paulo Santos | B24: MF | C24: 28 | D24: 16 | E24: 20 | F24: 35 | G24: 2 | H24: 0 | I24: 3600000 | J24: 52000000 | K24: 46022 | L24: =D24*2+E24 -> 52 | M24: =ROUND(L24/F24,2) -> 1.49 | N24: =MAX(0,MIN(10,10-(G24*0.3+H24*2))) -> 9.4 | O24: =IF(M24>=2,"Elite",IF(M24>=1.5,"Excellent",IF(M24>=1,"Good",IF(M24>=0.5,"Average","Below Average")))) -> Good | P24: =IFERROR(J24/L24,"No Goals/Assists") -> 1000000 | Q24: =IFERROR(I24/L24,"No data") -> 69230.769 | R24: =IF(YEAR(K24)<=2025,"Urgent",IF(YEAR(K24)=2026,"Soon","Long Term")) -> Urgent | S24: =IF(AND(O24="Elite",C24<28),"A",IF(AND(O24="Excellent",C24<30),"B",IF(O24="Good","C","Monitor"))) -> C | T24: =_xlfn.LET(_xlpm.TotalPts,D24*2+E24,_xlpm.AvgPts,_xlpm.TotalPts/F24,IF(_xlpm.AvgPts>=1.5,"Star","Regular")) -> Regular | U24: {=PLAYERVALUE(D24,E24,I24)} -> 14.444444
A25: Erik Johansson | B25: FW | C25: 29 | D25: 25 | E25: 11 | F25: 36 | G25: 4 | H25: 1 | I25: 4800000 | J25: 70000000 | K25: 46387 | L25: =D25*2+E25 -> 61 | M25: =ROUND(L25/F25,2) -> 1.69 | N25: =MAX(0,MIN(10,10-(G25*0.3+H25*2))) -> 6.8 | O25: =IF(M25>=2,"Elite",IF(M25>=1.5,"Excellent",IF(M25>=1,"Good",IF(M25>=0.5,"Average","Below Average")))) -> Excellent | P25: =IFERROR(J25/L25,"No Goals/Assists") -> 1147541 | Q25: =IFERROR(I25/L25,"No data") -> 78688.525 | R25: =IF(YEAR(K25)<=2025,"Urgent",IF(YEAR(K25)=2026,"Soon","Long Term")) -> Soon | S25: =IF(AND(O25="Elite",C25<28),"A",IF(AND(O25="Excellent",C25<30),"B",IF(O25="Good","C","Monitor"))) -> B | T25: =_xlfn.LET(_xlpm.TotalPts,D25*2+E25,_xlpm.AvgPts,_xlpm.TotalPts/F25,IF(_xlpm.AvgPts>=1.5,"Star","Regular")) -> Star | U25: {=PLAYERVALUE(D25,E25,I25)} -> 12.708333
A26: Diego Lopez | B26: GK | C26: 33 | D26: 0 | E26: 0 | F26: 28 | G26: 8 | H26: 2 | I26: 2500000 | J26: 25000000 | K26: 45838 | L26: =D26*2+E26 -> 0 | M26: =ROUND(L26/F26,2) -> 0 | N26: =MAX(0,MIN(10,10-(G26*0.3+H26*2))) -> 3.6 | O26: =IF(M26>=2,"Elite",IF(M26>=1.5,"Excellent",IF(M26>=1,"Good",IF(M26>=0.5,"Average","Below Average")))) -> Below Average | P26: =IFERROR(J26/L26,"No Goals/Assists") -> No Goals/Assists | Q26: =IFERROR(I26/L26,"No data") -> No data | R26: =IF(YEAR(K26)<=2025,"Urgent",IF(YEAR(K26)=2026,"Soon","Long Term")) -> Urgent | S26: =IF(AND(O26="Elite",C26<28),"A",IF(AND(O26="Excellent",C26<30),"B",IF(O26="Good","C","Monitor"))) -> Monitor | T26: =_xlfn.LET(_xlpm.TotalPts,D26*2+E26,_xlpm.AvgPts,_xlpm.TotalPts/F26,IF(_xlpm.AvgPts>=1.5,"Star","Regular")) -> Regular | U26: {=PLAYERVALUE(D26,E26,I26)} -> 0
A27: Antoine Dubois | B27: FW | C27: 24 | D27: 35 | E27: 12 | F27: 37 | G27: 2 | H27: 0 | I27: 7000000 | J27: 95000000 | K27: 46568 | L27: =D27*2+E27 -> 82 | M27: =ROUND(L27/F27,2) -> 2.22 | N27: =MAX(0,MIN(10,10-(G27*0.3+H27*2))) -> 9.4 | O27: =IF(M27>=2,"Elite",IF(M27>=1.5,"Excellent",IF(M27>=1,"Good",IF(M27>=0.5,"Average","Below Average")))) -> Elite | P27: =IFERROR(J27/L27,"No Goals/Assists") -> 1158536.6 | Q27: =IFERROR(I27/L27,"No data") -> 85365.854 | R27: =IF(YEAR(K27)<=2025,"Urgent",IF(YEAR(K27)=2026,"Soon","Long Term")) -> Long Term | S27: =IF(AND(O27="Elite",C27<28),"A",IF(AND(O27="Excellent",C27<30),"B",IF(O27="Good","C","Monitor"))) -> A | T27: =_xlfn.LET(_xlpm.TotalPts,D27*2+E27,_xlpm.AvgPts,_xlpm.TotalPts/F27,IF(_xlpm.AvgPts>=1.5,"Star","Regular")) -> Star | U27: {=PLAYERVALUE(D27,E27,I27)} -> 11.714286

Sheet Section 2
A1: SECTION 2
A2: use name manager and the functions suggested if so) | M2: Q# | N2: max | P2: score
A3: 1) Team/League/Stadium | M3: Q1 | N3: 1 | O3: 1 | P3: =O3*N3 -> 1
A4: 2)Capacity (USE MATCH, INDEX) | M4: Q2 | N4: 2 | O4: 1 | P4: =O4*N4 -> 2
A5: 3)Ticket price ( USE MATCH/INDEX) | M5: Q3 | N5: 2 | O5: 1 | P5: =O5*N5 -> 2
A6: 4) Coach/Revenue=ave attendance*ticket price | M6: Q4 | N6: 1 | O6: 1 | P6: =O6*N6 -> 1
A7: 5)Attendance %average attandance/capacity | M7: Q5 | N7: 1 | O7: 1 | P7: =O7*N7 -> 1
A8: 6) create the two drop-downs ( one with the team name and the other with (League/Stadium/Capacity/Ticket price/Coach name/revenue/Attendance%) | M8: Q6 | N8: 1 | O8: 1 | P8: =O8*N8 -> 1
A9: 7) Using the previous drop-downs highlight the corresponding cell in the table | M9: Q7 | N9: 5 | O9: 1 | P9: =O9*N9 -> 5
A10: 8) FILTER+CHOOSECOLS: Use FILTER to get teams with Att%>60%, then CHOOSECOLS to show only Team Name and Revenue columns | M10: Q8 | N10: 5 | O10: 1 | P10: =O10*N10 -> 5
A11: 9) LET+FILTER: Using LET, define avgRev=AVERAGE(Revenue), then FILTER teams where Revenue > avgRev, return Team Name & Revenue | M11: Q9 | N11: 5 | O11: 1 | P11: =O11*N11 -> 5
A12: 10) VSTACK: Stack La Liga teams ON TOP OF Bundesliga teams (Team Name & League only) using VSTACK+FILTER+CHOOSECOLS | M12: Q10 | N12: 5 | O12: 1 | P12: =O12*N12 -> 5
C13: Q1 | D13: Q1 | E13: Q1 | F13: Q2 | G13: Q3 | H13: Q4 | I13: Q4 | J13: Q5
A14: Team ID | B14: Avg Attendance | C14: Team Name | D14: League | E14: Stadium | F14: Capacity | G14: Ticket Price | H14: Coach Name | I14: Revenue | J14: Attendance %
A15: T001 | B15: 58000 | C15: =INDEX(B$56:B$63,MATCH(A15,I$56:I$63,0)) -> Real Madrid | D15: =INDEX(C$56:C$63,MATCH(A15,I$56:I$63,0)) -> La Liga | E15: =INDEX(D$56:D$63,MATCH(A15,I$56:I$63,0)) -> Santiago Bernabéu | F15: =INDEX(B$66:B$73,MATCH(E15,A$66:A$73,0)) -> 81044 | G15: =INDEX(G$56:G$60,MATCH(D15,F$56:F$60,0)) -> 75 | H15: =INDEX(K$56:K$63,MATCH(A15,I$56:I$63,0)) -> Ancelotti | I15: =B15*G15 -> 4350000 | J15: =B15/F15 -> 0.71566063
A16: T002 | B16: 72000 | C16: =INDEX(B$56:B$63,MATCH(A16,I$56:I$63,0)) -> FC Barcelona | D16: =INDEX(C$56:C$63,MATCH(A16,I$56:I$63,0)) -> La Liga | E16: =INDEX(D$56:D$63,MATCH(A16,I$56:I$63,0)) -> Camp Nou | F16: =INDEX(B$66:B$73,MATCH(E16,A$66:A$73,0)) -> 99354 | G16: =INDEX(G$56:G$60,MATCH(D16,F$56:F$60,0)) -> 75 | H16: =INDEX(K$56:K$63,MATCH(A16,I$56:I$63,0)) -> Xavi | I16: =B16*G16 -> 5400000 | J16: =B16/F16 -> 0.72468144
A17: T003 | B17: 52000 | C17: =INDEX(B$56:B$63,MATCH(A17,I$56:I$63,0)) -> Manchester United | D17: =INDEX(C$56:C$63,MATCH(A17,I$56:I$63,0)) -> Premier League | E17: =INDEX(D$56:D$63,MATCH(A17,I$56:I$63,0)) -> Old Trafford | F17: =INDEX(B$66:B$73,MATCH(E17,A$66:A$73,0)) -> 74140 | G17: =INDEX(G$56:G$60,MATCH(D17,F$56:F$60,0)) -> 85 | H17: =INDEX(K$56:K$63,MATCH(A17,I$56:I$63,0)) -> Ten Hag | I17: =B17*G17 -> 4420000 | J17: =B17/F17 -> 0.70137578
A18: T004 | B18: 61000 | C18: =INDEX(B$56:B$63,MATCH(A18,I$56:I$63,0)) -> Bayern Munich | D18: =INDEX(C$56:C$63,MATCH(A18,I$56:I$63,0)) -> Bundesliga | E18: =INDEX(D$56:D$63,MATCH(A18,I$56:I$63,0)) -> Allianz Arena | F18: =INDEX(B$66:B$73,MATCH(E18,A$66:A$73,0)) -> 75024 | G18: =INDEX(G$56:G$60,MATCH(D18,F$56:F$60,0)) -> 45 | H18: =INDEX(K$56:K$63,MATCH(A18,I$56:I$63,0)) -> Tuchel | I18: =B18*G18 -> 2745000 | J18: =B18/F18 -> 0.81307315
A19: T005 | B19: 38000 | C19: =INDEX(B$56:B$63,MATCH(A19,I$56:I$63,0)) -> Paris SG | D19: =INDEX(C$56:C$63,MATCH(A19,I$56:I$63,0)) -> Ligue 1 | E19: =INDEX(D$56:D$63,MATCH(A19,I$56:I$63,0)) -> Parc des Princes | F19: =INDEX(B$66:B$73,MATCH(E19,A$66:A$73,0)) -> 47929 | G19: =INDEX(G$56:G$60,MATCH(D19,F$56:F$60,0)) -> 55 | H19: =INDEX(K$56:K$63,MATCH(A19,I$56:I$63,0)) -> Enrique | I19: =B19*G19 -> 2090000 | J19: =B19/F19 -> 0.79283941
A20: T006 | B20: 46000 | C20: =INDEX(B$56:B$63,MATCH(A20,I$56:I$63,0)) -> Liverpool | D20: =INDEX(C$56:C$63,MATCH(A20,I$56:I$63,0)) -> Premier League | E20: =INDEX(D$56:D$63,MATCH(A20,I$56:I$63,0)) -> Anfield | F20: =INDEX(B$66:B$73,MATCH(E20,A$66:A$73,0)) -> 53394 | G20: =INDEX(G$56:G$60,MATCH(D20,F$56:F$60,0)) -> 85 | H20: =INDEX(K$56:K$63,MATCH(A20,I$56:I$63,0)) -> Klopp | I20: =B20*G20 -> 3910000 | J20: =B20/F20 -> 0.86152002
A21: T007 | B21: 35000 | C21: =INDEX(B$56:B$63,MATCH(A21,I$56:I$63,0)) -> Juventus | D21: =INDEX(C$56:C$63,MATCH(A21,I$56:I$63,0)) -> Serie A | E21: =INDEX(D$56:D$63,MATCH(A21,I$56:I$63,0)) -> Allianz Stadium | F21: =INDEX(B$66:B$73,MATCH(E21,A$66:A$73,0)) -> 41507 | G21: =INDEX(G$56:G$60,MATCH(D21,F$56:F$60,0)) -> 50 | H21: =INDEX(K$56:K$63,MATCH(A21,I$56:I$63,0)) -> Allegri | I21: =B21*G21 -> 1750000 | J21: =B21/F21 -> 0.84323126
A22: T008 | B22: 68000 | C22: =INDEX(B$56:B$63,MATCH(A22,I$56:I$63,0)) -> Dortmund | D22: =INDEX(C$56:C$63,MATCH(A22,I$56:I$63,0)) -> Bundesliga | E22: =INDEX(D$56:D$63,MATCH(A22,I$56:I$63,0)) -> Signal Iduna Park | F22: =INDEX(B$66:B$73,MATCH(E22,A$66:A$73,0)) -> 81365 | G22: =INDEX(G$56:G$60,MATCH(D22,F$56:F$60,0)) -> 45 | H22: =INDEX(K$56:K$63,MATCH(A22,I$56:I$63,0)) -> Terzic | I22: =B22*G22 -> 3060000 | J22: =B22/F22 -> 0.83574018
A24: ANSWER AREA FOR Q6 – Q10
A26: Q6) Drop-down 1 → Team name: | B26: Real Madrid | C26: Q6) Drop-down 2 → Column: | D26: League
A28: Q7) Using drop-downs B26 (Team) & D26 (Column), apply Conditional Formatting on C15:J22 so the cell at the intersection of the selected team's row and selected column is highlighted.
A29: → Hint: use a formula-based CF rule like =AND($C15=B$26, C$14=D$26). No answer cell needed — the CF itself is the answer.
A31: Q8) FILTER+CHOOSECOLS → Enter formula in B32: | D31: Q9) LET+FILTER → Enter formula in E32: | G31: Q10) VSTACK → Enter formula in H32:
A32: Team Name | B32: {=_xlfn.CHOOSECOLS(_xlfn._xlws.FILTER(C15:J22,J15:J22>0.6),1,7)} -> Real Madrid | C32: 4350000 | D32: Team Name | E32: {=_xlfn.LET(_xlpm.avgRev,AVERAGE(I15:I22),_xlfn.CHOOSECOLS(_xlfn._xlws.FILTER(C15:J22,I15:I22>_xlpm.avgRev),1,7))} -> Real Madrid | F32: 4350000 | G32: Team Name | H32: {=_xlfn.VSTACK(_xlfn.CHOOSECOLS(_xlfn._xlws.FILTER(C15:J22,D15:D22="La Liga"),1,2),_xlfn.CHOOSECOLS(_xlfn._xlws.FILTER(C15:J22,D15:D22="Bundesliga"),1,2))} -> Real Madrid | I32: La Liga
B33: FC Barcelona | C33: 5400000 | E33: FC Barcelona | F33: 5400000 | H33: FC Barcelona | I33: La Liga
B34: Manchester United | C34: 4420000 | E34: Manchester United | F34: 4420000 | H34: Bayern Munich | I34: Bundesliga
B35: Bayern Munich | C35: 2745000 | E35: Liverpool | F35: 3910000 | H35: Dortmund | I35: Bundesliga
B36: Paris SG | C36: 2090000
B37: Liverpool | C37: 3910000
B38: Juventus | C38: 1750000
B39: Dortmund | C39: 3060000
A46: COMPLEX MULTI-CRITERIA ANALYSIS (Q11–Q14) — Answer in N:
A47: 11) Total revenue WHERE Att%>60% AND Capacity>50000 | E47: {=SUMPRODUCT((J15:J22>0.6)*(F15:F22>50000)*I15:I22)} -> 23885000 | H47: Q11 | I47: 2 | J47: 1 | K47: =J47*I47 -> 2
A48: 12) What % of total attendance is Premier League? | E48: {=SUMPRODUCT((D15:D22="Premier League")*B15:B22)/SUM(B15:B22)} -> 0.22790698 | H48: Q12 | I48: 5 | J48: 1 | K48: =J48*I48 -> 5
A49: 13) Count teams WHERE Price>AVG(all prices) AND Att%>AVG(all att%) | E49: {=SUMPRODUCT((G15:G22>AVERAGE(G15:G22))*(J15:J22>AVERAGE(J15:J22)))} -> 1 | H49: Q13 | I49: 5 | J49: 1 | K49: =J49*I49 -> 5
A50: 14) Complex - Avg Capacity for teams with Revenue>$3M in 'La Liga' OR 'Bundesliga' | E50: {=AVERAGE(_xlfn._xlws.FILTER(F15:F22,(I15:I22>3000000)*((D15:D22="La Liga")+(D15:D22="Bundesliga"))))} -> 87254.333 | H50: Q14 | I50: 5 | J50: 1 | K50: =J50*I50 -> 5
...

Sheet Section 3
A1: SECTION 3: TEXT FUNCTIONS & DATA CLEANING
A3: 1) remove spaces/invisible chars
A4: 2) EXTRACT TEAM: Get team after @
A5: 3) EMAIL: playerid@teamcode.com
A6: 4) REG YEAR: Extract 4 digits after 'REG'
A7: 5) PLAYER NUM: Extract 3 digits after year
A8: 6) AGE: From Birth Date to today
A9: 7) FULL NAME: 'LastName, FirstName' in PROPER case
A10: 8) USERNAME: first3(lastname)+last2(year)+number (lowercase) Ex:'mar20001'
A11: 9) LET+TEXTJOIN: Using LET, define fn=PROPER(FirstName), ln=PROPER(LastName), return TEXTJOIN(" ",TRUE,fn,ln,"(",Position,")") → e.g. 'Lionel Martinez (FW)'
A12: 10) LAMBDA: In Name Manager, create a named LAMBDA called 'CLEANID' with one parameter (a cell reference to a Player ID in column A). It should return TRIM(CLEAN(SUBSTITUTE(cell,CHAR(8203),""))). Then in the LAMBDA Clean column (P), call =CLEANID(A17) for each player to remove spaces, invisible chars & zero-width spaces.
G15: Q1 | H15: Q2 | I15: Q3 | J15: Q4 | K15: Q5 | L15: Q6 | M15: Q7 | N15: Q8 | O15: Q9 | P15: Q10
A16: Player ID (Messy) | B16: First Name | C16: Last Name | D16: Position | E16: Birth Date | G16: Clean ID | H16: Team Code | I16: Email | J16: Reg Year | K16: Player Num | L16: Age | M16: Full Name | N16: Username | O16: LET Display | P16: LAMBDA Clean
A17: REG2020001 @RealM​adrid | B17: LIONEL | C17: martinez | D17: FW | E17: 35869 | G17: =TRIM(CLEAN(SUBSTITUTE(SUBSTITUTE(SUBSTITUTE(SUBSTITUTE(A17,_xlfn.UNICHAR(8203),""),_xlfn.UNICHAR(8204),""),_xlfn.UNICHAR(65279),"")," ",""))) -> REG2020001@RealMadrid | H17: =MID(G17,FIND("@",G17)+1,LEN(G17)) -> RealMadrid | I17: =LOWER(LEFT(G17,FIND("@",G17)-1))&"@"&LOWER(H17)&".com" -> reg2020001@realmadrid.com | J17: =MID(G17,FIND("REG",G17)+3,4) -> 2020 | K17: =MID(G17,FIND("REG",G17)+7,3) -> 001 | L17: =DATEDIF(E17,TODAY(),"Y") -> 27 | M17: =PROPER(C17)&", "&PROPER(B17) -> Martinez, Lionel | N17: =LOWER(LEFT(C17,3)&RIGHT(J17,2)&K17) -> mar20001 | O17: =_xlfn.LET(_xlpm.fn,PROPER(B17),_xlpm.ln,PROPER(C17),_xlfn.TEXTJOIN(" ",TRUE,_xlpm.fn,_xlpm.ln,"("&D17&")")) -> Lionel Martinez (FW) | P17: {=CLEANID(A17)} -> REG2020001@RealMadrid
A18: REG2019000@ Barcelona﻿ | B18: cristian | C18: RODRIGUEZ | D18: MF | E18: 34537 | G18: =TRIM(CLEAN(SUBSTITUTE(SUBSTITUTE(SUBSTITUTE(SUBSTITUTE(A18,_xlfn.UNICHAR(8203),""),_xlfn.UNICHAR(8204),""),_xlfn.UNICHAR(65279),"")," ",""))) -> REG2019000@Barcelona | H18: =MID(G18,FIND("@",G18)+1,LEN(G18)) -> Barcelona | I18: =LOWER(LEFT(G18,FIND("@",G18)-1))&"@"&LOWER(H18)&".com" -> reg2019000@barcelona.com | J18: =MID(G18,FIND("REG",G18)+3,4) -> 2019 | K18: =MID(G18,FIND("REG",G18)+7,3) -> 000 | L18: =DATEDIF(E18,TODAY(),"Y") -> 31 | M18: =PROPER(C18)&", "&PROPER(B18) -> Rodriguez, Cristian | N18: =LOWER(LEFT(C18,3)&RIGHT(J18,2)&K18) -> rod19000 | O18: =_xlfn.LET(_xlpm.fn,PROPER(B18),_xlpm.ln,PROPER(C18),_xlfn.TEXTJOIN(" ",TRUE,_xlpm.fn,_xlpm.ln,"("&D18&")")) -> Cristian Rodriguez (MF) | P18: {=CLEANID(A18)} -> REG2019000@Barcelona
A19: REG2021156 @ManUtd‌ | B19: Kevin | C19: anderson | D19: MF | E19: 36472 | G19: =TRIM(CLEAN(SUBSTITUTE(SUBSTITUTE(SUBSTITUTE(SUBSTITUTE(A19,_xlfn.UNICHAR(8203),""),_xlfn.UNICHAR(8204),""),_xlfn.UNICHAR(65279),"")," ",""))) -> REG2021156@ManUtd | H19: =MID(G19,FIND("@",G19)+1,LEN(G19)) -> ManUtd | I19: =LOWER(LEFT(G19,FIND("@",G19)-1))&"@"&LOWER(H19)&".com" -> reg2021156@manutd.com | J19: =MID(G19,FIND("REG",G19)+3,4) -> 2021 | K19: =MID(G19,FIND("REG",G19)+7,3) -> 156 | L19: =DATEDIF(E19,TODAY(),"Y") -> 26 | M19: =PROPER(C19)&", "&PROPER(B19) -> Anderson, Kevin | N19: =LOWER(LEFT(C19,3)&RIGHT(J19,2)&K19) -> and21156 | O19: =_xlfn.LET(_xlpm.fn,PROPER(B19),_xlpm.ln,PROPER(C19),_xlfn.TEXTJOIN(" ",TRUE,_xlpm.fn,_xlpm.ln,"("&D19&")")) -> Kevin Anderson (MF) | P19: {=CLEANID(A19)} -> REG2021156@ManUtd
A20: REG2018234@Bay​ern | B20: ROBERT | C20: silva | D20: FW | E20: 34849 | G20: =TRIM(CLEAN(SUBSTITUTE(SUBSTITUTE(SUBSTITUTE(SUBSTITUTE(A20,_xlfn.UNICHAR(8203),""),_xlfn.UNICHAR(8204),""),_xlfn.UNICHAR(65279),"")," ",""))) -> REG2018234@Bayern | H20: =MID(G20,FIND("@",G20)+1,LEN(G20)) -> Bayern | I20: =LOWER(LEFT(G20,FIND("@",G20)-1))&"@"&LOWER(H20)&".com" -> reg2018234@bayern.com | J20: =MID(G20,FIND("REG",G20)+3,4) -> 2018 | K20: =MID(G20,FIND("REG",G20)+7,3) -> 234 | L20: =DATEDIF(E20,TODAY(),"Y") -> 30 | M20: =PROPER(C20)&", "&PROPER(B20) -> Silva, Robert | N20: =LOWER(LEFT(C20,3)&RIGHT(J20,2)&K20) -> sil18234 | O20: =_xlfn.LET(_xlpm.fn,PROPER(B20),_xlpm.ln,PROPER(C20),_xlfn.TEXTJOIN(" ",TRUE,_xlpm.fn,_xlpm.ln,"("&D20&")")) -> Robert Silva (FW) | P20: {=CLEANID(A20)} -> REG2018234@Bayern
A21: REG2022089 @PSG﻿ | B21: mohamed | C21: Hassan | D21: DF | E21: 37146 | G21: =TRIM(CLEAN(SUBSTITUTE(SUBSTITUTE(SUBSTITUTE(SUBSTITUTE(A21,_xlfn.UNICHAR(8203),""),_xlfn.UNICHAR(8204),""),_xlfn.UNICHAR(65279),"")," ",""))) -> REG2022089@PSG | H21: =MID(G21,FIND("@",G21)+1,LEN(G21)) -> PSG | I21: =LOWER(LEFT(G21,FIND("@",G21)-1))&"@"&LOWER(H21)&".com" -> reg2022089@psg.com | J21: =MID(G21,FIND("REG",G21)+3,4) -> 2022 | K21: =MID(G21,FIND("REG",G21)+7,3) -> 089 | L21: =DATEDIF(E21,TODAY(),"Y") -> 24 | M21: =PROPER(C21)&", "&PROPER(B21) -> Hassan, Mohamed | N21: =LOWER(LEFT(C21,3)&RIGHT(J21,2)&K21) -> has22089 | O21: =_xlfn.LET(_xlpm.fn,PROPER(B21),_xlpm.ln,PROPER(C21),_xlfn.TEXTJOIN(" ",TRUE,_xlpm.fn,_xlpm.ln,"("&D21&")")) -> Mohamed Hassan (DF) | P21: {=CLEANID(A21)} -> REG2022089@PSG
A22: REG2020045@ Liverpool | B22: James | C22: WILSON | D22: FW | E22: 35479 | G22: =TRIM(CLEAN(SUBSTITUTE(SUBSTITUTE(SUBSTITUTE(SUBSTITUTE(A22,_xlfn.UNICHAR(8203),""),_xlfn.UNICHAR(8204),""),_xlfn.UNICHAR(65279),"")," ",""))) -> REG2020045@Liverpool | H22: =MID(G22,FIND("@",G22)+1,LEN(G22)) -> Liverpool | I22: =LOWER(LEFT(G22,FIND("@",G22)-1))&"@"&LOWER(H22)&".com" -> reg2020045@liverpool.com | J22: =MID(G22,FIND("REG",G22)+3,4) -> 2020 | K22: =MID(G22,FIND("REG",G22)+7,3) -> 045 | L22: =DATEDIF(E22,TODAY(),"Y") -> 29 | M22: =PROPER(C22)&", "&PROPER(B22) -> Wilson, James | N22: =LOWER(LEFT(C22,3)&RIGHT(J22,2)&K22) -> wil20045 | O22: =_xlfn.LET(_xlpm.fn,PROPER(B22),_xlpm.ln,PROPER(C22),_xlfn.TEXTJOIN(" ",TRUE,_xlpm.fn,_xlpm.ln,"("&D22&")")) -> James Wilson (FW) | P22: {=CLEANID(A22)} -> REG2020045@Liverpool
A23: REG2021078 @Juventus‌ | B23: LUIS | C23: fernandez | D23: MF | E23: 35302 | G23: =TRIM(CLEAN(SUBSTITUTE(SUBSTITUTE(SUBSTITUTE(SUBSTITUTE(A23,_xlfn.UNICHAR(8203),""),_xlfn.UNICHAR(8204),""),_xlfn.UNICHAR(65279),"")," ",""))) -> REG2021078@Juventus | H23: =MID(G23,FIND("@",G23)+1,LEN(G23)) -> Juventus | I23: =LOWER(LEFT(G23,FIND("@",G23)-1))&"@"&LOWER(H23)&".com" -> reg2021078@juventus.com | J23: =MID(G23,FIND("REG",G23)+3,4) -> 2021 | K23: =MID(G23,FIND("REG",G23)+7,3) -> 078 | L23: =DATEDIF(E23,TODAY(),"Y") -> 29 | M23: =PROPER(C23)&", "&PROPER(B23) -> Fernandez, Luis | N23: =LOWER(LEFT(C23,3)&RIGHT(J23,2)&K23) -> fer21078 | O23: =_xlfn.LET(_xlpm.fn,PROPER(B23),_xlpm.ln,PROPER(C23),_xlfn.TEXTJOIN(" ",TRUE,_xlpm.fn,_xlpm.ln,"("&D23&")")) -> Luis Fernandez (MF) | P23: {=CLEANID(A23)} -> REG2021078@Juventus
A24: REG2019167@Dor​tmund | B24: marco | C24: Rossi | D24: DF | E24: 34431 | G24: =TRIM(CLEAN(SUBSTITUTE(SUBSTITUTE(SUBSTITUTE(SUBSTITUTE(A24,_xlfn.UNICHAR(8203),""),_xlfn.UNICHAR(8204),""),_xlfn.UNICHAR(65279),"")," ",""))) -> REG2019167@Dortmund | H24: =MID(G24,FIND("@",G24)+1,LEN(G24)) -> Dortmund | I24: =LOWER(LEFT(G24,FIND("@",G24)-1))&"@"&LOWER(H24)&".com" -> reg2019167@dortmund.com | J24: =MID(G24,FIND("REG",G24)+3,4) -> 2019 | K24: =MID(G24,FIND("REG",G24)+7,3) -> 167 | L24: =DATEDIF(E24,TODAY(),"Y") -> 31 | M24: =PROPER(C24)&", "&PROPER(B24) -> Rossi, Marco | N24: =LOWER(LEFT(C24,3)&RIGHT(J24,2)&K24) -> ros19167 | O24: =_xlfn.LET(_xlpm.fn,PROPER(B24),_xlpm.ln,PROPER(C24),_xlfn.TEXTJOIN(" ",TRUE,_xlpm.fn,_xlpm.ln,"("&D24&")")) -> Marco Rossi (DF) | P24: {=CLEANID(A24)} -> REG2019167@Dortmund
A25: REG2023234@RealMadrid | B25: paulo | C25: SANTOS | D25: MF | E25: 37417 | G25: =TRIM(CLEAN(SUBSTITUTE(SUBSTITUTE(SUBSTITUTE(SUBSTITUTE(A25,_xlfn.UNICHAR(8203),""),_xlfn.UNICHAR(8204),""),_xlfn.UNICHAR(65279),"")," ",""))) -> REG2023234@RealMadrid | H25: =MID(G25,FIND("@",G25)+1,LEN(G25)) -> RealMadrid | I25: =LOWER(LEFT(G25,FIND("@",G25)-1))&"@"&LOWER(H25)&".com" -> reg2023234@realmadrid.com | J25: =MID(G25,FIND("REG",G25)+3,4) -> 2023 | K25: =MID(G25,FIND("REG",G25)+7,3) -> 234 | L25: =DATEDIF(E25,TODAY(),"Y") -> 23 | M25: =PROPER(C25)&", "&PROPER(B25) -> Santos, Paulo | N25: =LOWER(LEFT(C25,3)&RIGHT(J25,2)&K25) -> san23234 | O25: =_xlfn.LET(_xlpm.fn,PROPER(B25),_xlpm.ln,PROPER(C25),_xlfn.TEXTJOIN(" ",TRUE,_xlpm.fn,_xlpm.ln,"("&D25&")")) -> Paulo Santos (MF) | P25: {=CLEANID(A25)} -> REG2023234@RealMadrid
A26: REG2020000 @Bayern﻿ | B26: ERIK | C26: johansson | D26: GK | E26: 33943 | G26: =TRIM(CLEAN(SUBSTITUTE(SUBSTITUTE(SUBSTITUTE(SUBSTITUTE(A26,_xlfn.UNICHAR(8203),""),_xlfn.UNICHAR(8204),""),_xlfn.UNICHAR(65279),"")," ",""))) -> REG2020000@Bayern | H26: =MID(G26,FIND("@",G26)+1,LEN(G26)) -> Bayern | I26: =LOWER(LEFT(G26,FIND("@",G26)-1))&"@"&LOWER(H26)&".com" -> reg2020000@bayern.com | J26: =MID(G26,FIND("REG",G26)+3,4) -> 2020 | K26: =MID(G26,FIND("REG",G26)+7,3) -> 000 | L26: =DATEDIF(E26,TODAY(),"Y") -> 33 | M26: =PROPER(C26)&", "&PROPER(B26) -> Johansson, Erik | N26: =LOWER(LEFT(C26,3)&RIGHT(J26,2)&K26) -> joh20000 | O26: =_xlfn.LET(_xlpm.fn,PROPER(B26),_xlpm.ln,PROPER(C26),_xlfn.TEXTJOIN(" ",TRUE,_xlpm.fn,_xlpm.ln,"("&D26&")")) -> Erik Johansson (GK) | P26: {=CLEANID(A26)} -> REG2020000@Bayern
A30: Q# | B30: max | D30: score
A31: Q1 | B31: 1 | C31: 1 | D31: =C31*B31 -> 1
A32: Q2 | B32: 1 | C32: 1 | D32: =C32*B32 -> 1
A33: Q3 | B33: 2 | C33: 1 | D33: =C33*B33 -> 2
A34: Q4 | B34: 2 | C34: 1 | D34: =C34*B34 -> 2
A35: Q5 | B35: 2 | C35: 1 | D35: =C35*B35 -> 2
A36: Q6 | B36: 5 | C36: 1 | D36: =C36*B36 -> 5
A37: Q7 | B37: 2 | C37: 1 | D37: =C37*B37 -> 2
A38: Q8 | B38: 5 | C38: 1 | D38: =C38*B38 -> 5
A39: Q9 | B39: 5 | C39: 1 | D39: =C39*B39 -> 5
A40: Q10 | B40: 5 | C40: 1 | D40: =C40*B40 -> 5
B41: =SUM(B31:B40) -> 30 | C41: total | D41: =SUM(D31:D40) -> 30

Sheet Section 4
A1: SECTION 4: TABLES & CONDITIONAL FORMATTING: use tables in this section
A3: 1) Convert A12:G37 to a TABLE named 'MatchResults' (columns A–G contain the source data)
A4: 2) Add 3 calculated columns to the table: GoalDiff (Home–Away), Result Home (Win/Loss/Draw based on GoalDiff), Result Away (opposite)
A5: 3) Apply Color Scales conditional formatting on the Attendance column (green=high, red=low)
A6: 4) Apply Icon Sets on Result Home and Result Away columns: ✔ for Win, ✖ for Loss, ➖ for Draw
A7: 5) Insert a Slicer for the Home Team column | J7: Q6 Answer:
A8: 6) Using AVERAGEIFS, calculate: average Attendance where Home Team='Bayern', Result Home='Win', and Home Goals>1. Answer in J8 → | J8: =IFERROR(AVERAGEIFS(G13:G37,C13:C37,"Bayern",I13:I37,"Win",E13:E37,">1"),"No matching games") -> No matching games
A9: 7) DYNAMIC ROW HIGHLIGHT: Create a drop-down in L13 listing all unique Home Team names. Then apply a Conditional Formatting rule on the data range A13:J37 using a formula so that when a team is selected, the ENTIRE ROW of every match where that team plays at home is highlighted in light blue.
A10: 8) DYNAMIC COLUMN HIGHLIGHT: Create a drop-down in L16 listing the column headers (Date, Home Team, Away Team, etc.). Then apply a Conditional Formatting rule on A12:J37 using a formula so that when a header is selected, the ENTIRE COLUMN under that header is highlighted in light green.
H11: Q2 | I11: Q2 | J11: Q2
A12: Match ID | B12: Date | C12: Home Team | D12: Away Team | E12: Home Goals | F12: Away Goals | G12: Attendance | H12: Goal Diff | I12: Result home | J12: Result away
A13: M001 | B13: 45914 | C13: Real Madrid | D13: Man United | E13: 0 | F13: 0 | G13: 31295 | H13: =E13-F13 -> 0 | I13: =IF(H13>0,"Win",IF(H13<0,"Loss","Draw")) -> Draw | J13: =IF(H13<0,"Win",IF(H13>0,"Loss","Draw")) -> Draw | L13: Q7) Team drop-down ↓ | N13: Q# | O13: max | Q13: score
A14: M002 | B14: 45680 | C14: Barcelona | D14: Dortmund | E14: 0 | F14: 5 | G14: 80288 | H14: =E14-F14 -> -5 | I14: =IF(H14>0,"Win",IF(H14<0,"Loss","Draw")) -> Loss | J14: =IF(H14<0,"Win",IF(H14>0,"Loss","Draw")) -> Win | L14: Barcelona | N14: Q1 | O14: 1 | P14: 1 | Q14: =P14*O14 -> 1
A15: M003 | B15: 45675 | C15: PSG | D15: Juventus | E15: 3 | F15: 5 | G15: 34988 | H15: =E15-F15 -> -2 | I15: =IF(H15>0,"Win",IF(H15<0,"Loss","Draw")) -> Loss | J15: =IF(H15<0,"Win",IF(H15>0,"Loss","Draw")) -> Win | L15: Q8) Column drop-down ↓ | N15: Q2 | O15: 1 | P15: 1 | Q15: =P15*O15 -> 1
A16: M004 | B16: 45850 | C16: Barcelona | D16: Man United | E16: 1 | F16: 0 | G16: 82528 | H16: =E16-F16 -> 1 | I16: =IF(H16>0,"Win",IF(H16<0,"Loss","Draw")) -> Win | J16: =IF(H16<0,"Win",IF(H16>0,"Loss","Draw")) -> Loss | L16: Home Team | N16: Q3 | O16: 3 | P16: 1 | Q16: =P16*O16 -> 3
A17: M005 | B17: 45881 | C17: Juventus | D17: Dortmund | E17: 4 | F17: 0 | G17: 33454 | H17: =E17-F17 -> 4 | I17: =IF(H17>0,"Win",IF(H17<0,"Loss","Draw")) -> Win | J17: =IF(H17<0,"Win",IF(H17>0,"Loss","Draw")) -> Loss | N17: Q4 | O17: 2 | P17: 1 | Q17: =P17*O17 -> 2
A18: M006 | B18: 45834 | C18: PSG | D18: Liverpool | E18: 4 | F18: 3 | G18: 76692 | H18: =E18-F18 -> 1 | I18: =IF(H18>0,"Win",IF(H18<0,"Loss","Draw")) -> Win | J18: =IF(H18<0,"Win",IF(H18>0,"Loss","Draw")) -> Loss | N18: Q5 | O18: 3 | P18: 1 | Q18: =P18*O18 -> 3
A19: M007 | B19: 45824 | C19: Juventus | D19: Man United | E19: 3 | F19: 3 | G19: 29773 | H19: =E19-F19 -> 0 | I19: =IF(H19>0,"Win",IF(H19<0,"Loss","Draw")) -> Draw | J19: =IF(H19<0,"Win",IF(H19>0,"Loss","Draw")) -> Draw | N19: Q6 | O19: 5 | P19: 1 | Q19: =P19*O19 -> 5
A20: M008 | B20: 45842 | C20: Real Madrid | D20: Barcelona | E20: 5 | F20: 4 | G20: 58152 | H20: =E20-F20 -> 1 | I20: =IF(H20>0,"Win",IF(H20<0,"Loss","Draw")) -> Win | J20: =IF(H20<0,"Win",IF(H20>0,"Loss","Draw")) -> Loss | N20: Q7 | O20: 5 | P20: 1 | Q20: =P20*O20 -> 5
A21: M009 | B21: 45702 | C21: Barcelona | D21: Liverpool | E21: 0 | F21: 3 | G21: 71141 | H21: =E21-F21 -> -3 | I21: =IF(H21>0,"Win",IF(H21<0,"Loss","Draw")) -> Loss | J21: =IF(H21<0,"Win",IF(H21>0,"Loss","Draw")) -> Win | N21: Q8 | O21: 5 | P21: 1 | Q21: =P21*O21 -> 5
A22: M010 | B22: 45852 | C22: PSG | D22: Liverpool | E22: 3 | F22: 4 | G22: 51907 | H22: =E22-F22 -> -1 | I22: =IF(H22>0,"Win",IF(H22<0,"Loss","Draw")) -> Loss | J22: =IF(H22<0,"Win",IF(H22>0,"Loss","Draw")) -> Win | O22: =SUM(O14:O21) -> 25 | P22: total | Q22: =SUM(Q14:Q21) -> 25
A23: M011 | B23: 45690 | C23: Man United | D23: Liverpool | E23: 2 | F23: 2 | G23: 45687 | H23: =E23-F23 -> 0 | I23: =IF(H23>0,"Win",IF(H23<0,"Loss","Draw")) -> Draw | J23: =IF(H23<0,"Win",IF(H23>0,"Loss","Draw")) -> Draw
A24: M012 | B24: 45694 | C24: Real Madrid | D24: Juventus | E24: 3 | F24: 1 | G24: 30452 | H24: =E24-F24 -> 2 | I24: =IF(H24>0,"Win",IF(H24<0,"Loss","Draw")) -> Win | J24: =IF(H24<0,"Win",IF(H24>0,"Loss","Draw")) -> Loss
A25: M013 | B25: 45695 | C25: Bayern | D25: PSG | E25: 2 | F25: 4 | G25: 29839 | H25: =E25-F25 -> -2 | I25: =IF(H25>0,"Win",IF(H25<0,"Loss","Draw")) -> Loss | J25: =IF(H25<0,"Win",IF(H25>0,"Loss","Draw")) -> Win
A26: M014 | B26: 45702 | C26: Barcelona | D26: Bayern | E26: 1 | F26: 1 | G26: 81681 | H26: =E26-F26 -> 0 | I26: =IF(H26>0,"Win",IF(H26<0,"Loss","Draw")) -> Draw | J26: =IF(H26<0,"Win",IF(H26>0,"Loss","Draw")) -> Draw
A27: M015 | B27: 45855 | C27: Juventus | D27: Bayern | E27: 4 | F27: 3 | G27: 74879 | H27: =E27-F27 -> 1 | I27: =IF(H27>0,"Win",IF(H27<0,"Loss","Draw")) -> Win | J27: =IF(H27<0,"Win",IF(H27>0,"Loss","Draw")) -> Loss
A28: M016 | B28: 45743 | C28: Bayern | D28: Barcelona | E28: 2 | F28: 4 | G28: 63712 | H28: =E28-F28 -> -2 | I28: =IF(H28>0,"Win",IF(H28<0,"Loss","Draw")) -> Loss | J28: =IF(H28<0,"Win",IF(H28>0,"Loss","Draw")) -> Win
A29: M017 | B29: 45800 | C29: Bayern | D29: Real Madrid | E29: 2 | F29: 2 | G29: 64340 | H29: =E29-F29 -> 0 | I29: =IF(H29>0,"Win",IF(H29<0,"Loss","Draw")) -> Draw | J29: =IF(H29<0,"Win",IF(H29>0,"Loss","Draw")) -> Draw
A30: M018 | B30: 45869 | C30: Real Madrid | D30: PSG | E30: 3 | F30: 5 | G30: 58338 | H30: =E30-F30 -> -2 | I30: =IF(H30>0,"Win",IF(H30<0,"Loss","Draw")) -> Loss | J30: =IF(H30<0,"Win",IF(H30>0,"Loss","Draw")) -> Win
A31: M019 | B31: 45749 | C31: Liverpool | D31: Real Madrid | E31: 1 | F31: 3 | G31: 31979 | H31: =E31-F31 -> -2 | I31: =IF(H31>0,"Win",IF(H31<0,"Loss","Draw")) -> Loss | J31: =IF(H31<0,"Win",IF(H31>0,"Loss","Draw")) -> Win
A32: M020 | B32: 45831 | C32: Liverpool | D32: Barcelona | E32: 5 | F32: 3 | G32: 59737 | H32: =E32-F32 -> 2 | I32: =IF(H32>0,"Win",IF(H32<0,"Loss","Draw")) -> Win | J32: =IF(H32<0,"Win",IF(H32>0,"Loss","Draw")) -> Loss
A33: M021 | B33: 45826 | C33: Barcelona | D33: Juventus | E33: 5 | F33: 3 | G33: 46100 | H33: =E33-F33 -> 2 | I33: =IF(H33>0,"Win",IF(H33<0,"Loss","Draw")) -> Win | J33: =IF(H33<0,"Win",IF(H33>0,"Loss","Draw")) -> Loss
A34: M022 | B34: 45854 | C34: Dortmund | D34: Real Madrid | E34: 4 | F34: 4 | G34: 41349 | H34: =E34-F34 -> 0 | I34: =IF(H34>0,"Win",IF(H34<0,"Loss","Draw")) -> Draw | J34: =IF(H34<0,"Win",IF(H34>0,"Loss","Draw")) -> Draw
... A37: M025 | B37: 45767 | C37: Juventus | D37: Barcelona | E37: 2 | F37: 1 | G37: 43875 | H37: =E37-F37 -> 1 | I37: =IF(H37>0,"Win",IF(H37<0,"Loss","Draw")) -> Win | J37: =IF(H37<0,"Win",IF(H37>0,"Loss","Draw")) -> Loss

Sheet grading sheet
C15: Section1 | D15: Section2 | E15: Section3 | F15: Section4 | G15: TOTAL
B16: Maximun | C16: ='Section 1 '!X14 -> 35 | D16: ='Section 2'!I51 -> 45 | E16: ='Section 3'!B41 -> 30 | F16: ='Section 4'!O22 -> 25 | G16: =SUM(C16:F16) -> 135
B17: Grade | C17: ='Section 1 '!Z14 -> 35 | D17: ='Section 2'!K51 -> 45 | E17: ='Section 3'!D41 -> 30 | F17: ='Section 4'!Q22 -> 25 | G17: =SUM(C17:F17) -> 135
G18: =G17/G16 -> 1
